Workbook

Sheet merge
A1: Year | B1: Country | C1: Number | D1: Indicator | E1: Value
A2: 2021 | B2: Brazil | C2: 58059 | D2: Cereal yield (kg per hectare) | E2: 4477.4
A3: 2021 | B3: Brazil | C3: 58059 | D3: Inflation, consumer prices (annual %) | E3: 8.30165975585673
A4: 2021 | B4: Brazil | C4: 58059 | D4: Deposit interest rate (%) | E4: 4.3480539
A5: 2021 | B5: Brazil | C5: 58059 | D5: Lending interest rate (%) | E5: 30.0166666666667
A6: 2021 | B6: Brazil | C6: 58059 | D6: Central government debt, total (% of GDP) | E6: 85.0115036701985
A7: 2021 | B7: Brazil | C7: 58059 | D7: Military expenditure (% of GDP) | E7: 1.16368211072875
A8: 2021 | B8: Brazil | C8: 58059 | D8: GDP (current US$) | E8: 1670647399034.67
A9: 2021 | B9: Brazil | C9: 58059 | D9: Poverty headcount ratio at $2.15 a day (2017 PPP) (% of population) | E9: 5.8
A10: 2021 | B10: Brazil | C10: 58059 | D10: Labor force, total | E10: 106047171
A11: 2021 | B11: Brazil | C11: 58059 | D11: Unemployment, total (% of total labor force) (modeled ILO estimate) | E11: 13.159
A12: 2021 | B12: Brazil | C12: 58059 | D12: Birth rate, crude (per 1,000 people) | E12: 12.883
A13: 2021 | B13: Brazil | C13: 58059 | D13: High-technology exports (current US$) | E13: 6350114829
A14: 2021 | B14: Brazil | C14: 58059 | D14: GDP growth (annual %) | E14: 4.76260437908608
A15: 2021 | B15: Brazil | C15: 58059 | D15: people_sum | E15: 214326223
A16: 2021 | B16: Brazil | C16: 58059 | D16: Death rate, crude (per 1,000 people) | E16: 8.326
A17: 2021 | B17: Canada | C17: 22371 | D17: Cereal yield (kg per hectare) | E17: 3120
A18: 2021 | B18: Canada | C18: 22371 | D18: Inflation, consumer prices (annual %) | E18: 3.39519318527528
A19: 2021 | B19: Canada | C19: 22371 | D19: Research and development expenditure (% of GDP) | E19: 1.69727003574371
A20: 2021 | B20: Canada | C20: 22371 | D20: Central government debt, total (% of GDP) | E20: 71.0739602315819
A21: 2021 | B21: Canada | C21: 22371 | D21: Military expenditure (% of GDP) | E21: 1.26729446473527
A22: 2021 | B22: Canada | C22: 22371 | D22: GDP (current US$) | E22: 2007472181464.15
A23: 2021 | B23: Canada | C23: 22371 | D23: Government expenditure on education, total (% of GDP) | E23: 4.59400606155396
A24: 2021 | B24: Canada | C24: 22371 | D24: Labor force, total | E24: 20967796
A25: 2021 | B25: Canada | C25: 22371 | D25: Unemployment, total (% of total labor force) (modeled ILO estimate) | E25: 7.527
A26: 2021 | B26: Canada | C26: 22371 | D26: Birth rate, crude (per 1,000 people) | E26: 9.7
A27: 2021 | B27: Canada | C27: 22371 | D27: High-technology exports (current US$) | E27: 29239719472
A28: 2021 | B28: Canada | C28: 22371 | D28: GDP growth (annual %) | E28: 5.28695689105889
A29: 2021 | B29: Canada | C29: 22371 | D29: people_sum | E29: 38239864
A30: 2021 | B30: Canada | C30: 22371 | D30: Death rate, crude (per 1,000 people) | E30: 8.2
A31: 2021 | B31: China | C31: 23471 | D31: Cereal yield (kg per hectare) | E31: 6316.7
A32: 2021 | B32: China | C32: 23471 | D32: Inflation, consumer prices (annual %) | E32: 0.981015135544882
A33: 2021 | B33: China | C33: 23471 | D33: Deposit interest rate (%) | E33: 1.5
A34: 2021 | B34: China | C34: 23471 | D34: Lending interest rate (%) | E34: 4.35
A35: 2021 | B35: China | C35: 23471 | D35: Research and development expenditure (% of GDP) | E35: 2.4326000213623
A36: 2021 | B36: China | C36: 23471 | D36: Military expenditure (% of GDP) | E36: 1.61307386433133
A37: 2021 | B37: China | C37: 23471 | D37: GDP (current US$) | E37: 17820459508852.2
A38: 2021 | B38: China | C38: 23471 | D38: Government expenditure on education, total (% of GDP) | E38: 3.29784345626831
A39: 2021 | B39: China | C39: 23471 | D39: Labor force, total | E39: 780370660
A40: 2021 | B40: China | C40: 23471 | D40: Unemployment, total (% of total labor force) (modeled ILO estimate) | E40: 4.55
...

Sheet Sheet1
A1: Number | B1: Value | C1: Number(秩) | D1: Value(秩)
A2: 58059 | B2: 12.883 | C2: =VLOOKUP(A2,Sheet3!A:B,2,0) -> 27 | D2: =VLOOKUP(B2,Sheet2!A:B,2,0) -> 14
A3: 22371 | B3: 9.7 | C3: =VLOOKUP(A3,Sheet3!A:B,2,0) -> 11 | D3: =VLOOKUP(B3,Sheet2!A:B,2,0) -> 11
A4: 23471 | B4: 7.52 | C4: =VLOOKUP(A4,Sheet3!A:B,2,0) -> 12 | D4: =VLOOKUP(B4,Sheet2!A:B,2,0) -> 3
A5: 10495 | B5: 14.204 | C5: =VLOOKUP(A5,Sheet3!A:B,2,0) -> 8 | D5: =VLOOKUP(B5,Sheet2!A:B,2,0) -> 16
A6: 39303 | B6: 8.922 | C6: =VLOOKUP(A6,Sheet3!A:B,2,0) -> 17 | D6: =VLOOKUP(B6,Sheet2!A:B,2,0) -> 7
A7: 97074 | B7: 16.817 | C7: =VLOOKUP(A7,Sheet3!A:B,2,0) -> 29 | D7: =VLOOKUP(B7,Sheet2!A:B,2,0) -> 28
A8: 99463 | B8: 16.025 | C8: =VLOOKUP(A8,Sheet3!A:B,2,0) -> 32 | D8: =VLOOKUP(B8,Sheet2!A:B,2,0) -> 24
A9: 284291 | B9: 21.12 | C9: =VLOOKUP(A9,Sheet3!A:B,2,0) -> 39 | D9: =VLOOKUP(B9,Sheet2!A:B,2,0) -> 38
A10: 48727 | B10: 23.498 | C10: =VLOOKUP(A10,Sheet3!A:B,2,0) -> 20 | D10: =VLOOKUP(B10,Sheet2!A:B,2,0) -> 42
A11: 321149 | B11: 21.071 | C11: =VLOOKUP(A11,Sheet3!A:B,2,0) -> 40 | D11: =VLOOKUP(B11,Sheet2!A:B,2,0) -> 37
A12: 30662 | B12: 16.419 | C12: =VLOOKUP(A12,Sheet3!A:B,2,0) -> 15 | D12: =VLOOKUP(B12,Sheet2!A:B,2,0) -> 26
A13: 674739 | B13: 14.857 | C13: =VLOOKUP(A13,Sheet3!A:B,2,0) -> 41 | D13: =VLOOKUP(B13,Sheet2!A:B,2,0) -> 20
... A43: 189520 | B43: 15.573 | C43: =VLOOKUP(A43,Sheet3!A:B,2,0) -> 35 | D43: =VLOOKUP(B43,Sheet2!A:B,2,0) -> 21
C44: 21.5 | D44: 21.47619

Sheet Sheet2
A1: Value
A2: 6.77 | B2: 1
A3: 7.3 | B3: 2
A4: 7.52 | B4: 3
A5: 7.659 | B5: 4
A6: 8.889 | B6: 5
A7: 8.9 | B7: 6
A8: 8.922 | B8: 7
A9: 9 | B9: 8
A10: 9.6 | B10: 9
A11: 9.6 | B11: 10
A12: 9.7 | B12: 11
A13: 10.1 | B13: 12
... A43: 23.498 | B43: 42

Sheet Sheet3
A1: 3841 | B1: 1
A2: 4470 | B2: 2
A3: 4989 | B3: 3
A4: 5159 | B4: 4
A5: 5177 | B5: 5
A6: 7411 | B6: 6
A7: 9378 | B7: 7
A8: 10495 | B8: 8
A9: 13240 | B9: 9
A10: 19470 | B10: 10
A11: 22371 | B11: 11
A12: 23471 | B12: 12
... A42: 823057 | B42: 42
